Workbook

Sheet MONTHLY

Sheet Monitor CS Attempt
A1: Tracking | B1: Customer Name | C1: Contact | D1: Address | E1: Items | F1: COD Amount | G1: Attempt Reason | H1: Date | I1: 📜 Courier Timeline (Last 4) | J1: 🛒 Shopify Notes | K1: 📋 CS Status | L1: 📝 CS Resolution Note | M1: ⚡ Action | N1: 📲 Escalate
A2: 24120050021639 | B2: Manzoor Hussain | C2: 3143944980 | D2: Gali Tawasuli , Alamdar Road, Momin abad, Quetta Quetta | E2: Tipping Crew - L / Black (x1), Tipping Crew - L / White (x1) | F2: 2749 | G2: Attempted | H2: 46067.835 | I2: • Merchant Request For Re-Attempt • Delivery Under Review • Attempt Made: RFD(REFUSED TO RECEIVE) • Enroute for Delivery | J2: Order has been shipped via PostEx with Tracking 24120050021639. confirm not ans | N2: =HYPERLINK("https://api.whatsapp.com/send?text=" & ENCODEURL("🚨 *PostEx Attempt Follow-up*" & CHAR(10) & "📦 Tracking: " & A2 & CHAR(10) & "❌ Issue: " & G2 & CHAR(10) & "💬 CS Update: " & L2), "📲 Send to Courier") -> 📲 Send to Courier
A3: 23120050021855 | B3: Aimal Khan | C3: 3394849051 | D3: PAF Base Shahrah E Faisal Karachi Karachi | E3: Multi ref PUM-A - 2XL / White (x1), Multi ref PUM-A - 2XL / Black (x1) | F3: 3099 | G3: Attempted | H3: 46070.656 | I3: • Attempt Made: CNA(CUSTOMER NOT AVAILABLE) • Enroute for Delivery • Attempt Made: CNA(CUSTOMER NOT AVAILABLE) • Enroute for Delivery | J3: Order has been shipped via PostEx with Tracking 23120050021855. ok | N3: =HYPERLINK("https://api.whatsapp.com/send?text=" & ENCODEURL("🚨 *PostEx Attempt Follow-up*" & CHAR(10) & "📦 Tracking: " & A3 & CHAR(10) & "❌ Issue: " & G3 & CHAR(10) & "💬 CS Update: " & L3), "📲 Send to Courier") -> 📲 Send to Courier
A4: 27120050021727 | B4: Asim Risz | C4: 3245751049 | D4: Moscow Plaza Subway Building 3rd Floor Office No 6 Blue Area Islamabad Islamabad | E4: Multi ref PUM-A - M / White (x1), Multi ref PUM-A - M / Black (x1) | F4: 3099 | G4: Attempted | H4: 46066.564 | I4: • Merchant Request For Re-Attempt • Delivery Under Review • Attempt Made: CNA(CUSTOMER NOT AVAILABLE) • Enroute for Delivery | J4: Order has been shipped via PostEx with Tracking 27120050021727. rider na rabta nahi kiya | N4: =HYPERLINK("https://api.whatsapp.com/send?text=" & ENCODEURL("🚨 *PostEx Attempt Follow-up*" & CHAR(10) & "📦 Tracking: " & A4 & CHAR(10) & "❌ Issue: " & G4 & CHAR(10) & "💬 CS Update: " & L4), "📲 Send to Courier") -> 📲 Send to Courier
A5: 26120050021847 | B5: Shahrooz Wali | C5: 3425169661 | D5: Aga Khan University Karachi, University Center Building Karachi | E5: Multi ref PUM-A - M / White (x1), Multi ref PUM-A - M / Black (x1) | F5: 3099 | G5: Attempted | H5: 46070.656 | I5: • Attempt Made: CNA(CUSTOMER NOT AVAILABLE) • Enroute for Delivery • Attempt Made: CNA(CUSTOMER NOT AVAILABLE) • Enroute for Delivery | J5: Order has been shipped via PostEx with Tracking 26120050021847. confrm | N5: =HYPERLINK("https://api.whatsapp.com/send?text=" & ENCODEURL("🚨 *PostEx Attempt Follow-up*" & CHAR(10) & "📦 Tracking: " & A5 & CHAR(10) & "❌ Issue: " & G5 & CHAR(10) & "💬 CS Update: " & L5), "📲 Send to Courier") -> 📲 Send to Courier
A6: 22120050021869 | B6: Abu Bakar | C6: 3236551086 | D6: Nadeem Traders Shorkot cantt | E6: Tipping Crew - M / Black (x1), Tipping Crew - M / White (x1) | F6: 2749 | G6: Attempted | H6: 46070.656 | I6: • Merchant Request For Re-Attempt • Delivery Under Review • Attempt Made: OPN(CONSIGNEE WANTS TO OPEN PARCEL) • Enroute for Delivery | J6: Order has been shipped via PostEx with Tracking 22120050021869. confirm consignee want open parcel | N6: =HYPERLINK("https://api.whatsapp.com/send?text=" & ENCODEURL("🚨 *PostEx Attempt Follow-up*" & CHAR(10) & "📦 Tracking: " & A6 & CHAR(10) & "❌ Issue: " & G6 & CHAR(10) & "💬 CS Update: " & L6), "📲 Send to Courier") -> 📲 Send to Courier
A7: 22120050021862 | B7: Atif Rafiq Rafiq Rafiq | C7: 3224142431 | D7: Paradox London office#708 7th floor Haly tower DHA phase 2 Lahore Lahore | E7: ADI Multi Ref Stripes - XL / White (x1), ADI Multi Ref Stripes - XL / Black (x1) | F7: 3348 | G7: Attempted | H7: 46067.666 | I7: • Attempt Made: CNA(CUSTOMER NOT AVAILABLE) • Enroute for Delivery • Attempt Made: HCR(HOLD ON CONSIGNEE REQUEST) • Enroute for Delivery | J7: Order has been shipped via PostEx with Tracking 22120050021862. confirm | N7: =HYPERLINK("https://api.whatsapp.com/send?text=" & ENCODEURL("🚨 *PostEx Attempt Follow-up*" & CHAR(10) & "📦 Tracking: " & A7 & CHAR(10) & "❌ Issue: " & G7 & CHAR(10) & "💬 CS Update: " & L7), "📲 Send to Courier") -> 📲 Send to Courier
A8: 22120050021879 | B8: Farhan Saeed | C8: 3212447691 | D8: Rio center building saddar karachi flat no 216 2nd floor near attrium mall Karachi | E8: A | X Embroidery LOGO - XL / Black (x1), A | X Embroidery LOGO - XL / White (x1), A | X Embroidery LOGO - XL / Pista (x1) | F8: 4599 | G8: Attempted | H8: 46070.656 | I8: • Attempt Made: CNA(CUSTOMER NOT AVAILABLE) • Enroute for Delivery • Waiting for Delivery • Arrived at Transit Hub KHI | J8: Order has been shipped via PostEx with Tracking 22120050021879. open to allow | N8: =HYPERLINK("https://api.whatsapp.com/send?text=" & ENCODEURL("🚨 *PostEx Attempt Follow-up*" & CHAR(10) & "📦 Tracking: " & A8 & CHAR(10) & "❌ Issue: " & G8 & CHAR(10) & "💬 CS Update: " & L8), "📲 Send to Courier") -> 📲 Send to Courier
A9: 25120050021888 | B9: Muhammad RAMZAN | C9: 3004031405 | D9: Fauji Fresh n Freeze pvt limited 16km Pakptan road,Sahiwal SAHIWAL | E9: Multi ref PUM-A - L / White (x1), Multi ref PUM-A - L / Black (x1) | F9: 3348 | G9: Attempted | H9: 46070.656 | I9: • Attempt Made: CNA(CUSTOMER NOT AVAILABLE) • Enroute for Delivery • Waiting for Delivery • Arrived at Transit Hub SWL | J9: Order has been shipped via PostEx with Tracking 25120050021888. confirm | N9: =HYPERLINK("https://api.whatsapp.com/send?text=" & ENCODEURL("🚨 *PostEx Attempt Follow-up*" & CHAR(10) & "📦 Tracking: " & A9 & CHAR(10) & "❌ Issue: " & G9 & CHAR(10) & "💬 CS Update: " & L9), "📲 Send to Courier") -> 📲 Send to Courier

Sheet Payment Updates
A1: 🔑 MASTER KEY: | B1: Match by Tracking Number
A2: Order ID | B2: Tracking Number | C2: Type (D/R) | D2: COD Amount | E2: Charges | F2: Ref | G2: Date | H2: Courier Name | I2: Balance | J2: Status | K2: Recommendation | L2: Net Payout | M2: Comments | N2: Charges Trick | O2: 4% TAX ADD ON | P2: FINAL CHARGES | Q2: value paste(recheck)
A3: TR31268 | B3: 24120050023622 | C3: D | D3: 3149 | E3: 254.95 | F3: CPR-RAGFP443199 | G3: 46129 | H3: PostEx | I3: 3149 | J3: ✅ Done | K3: ✅ Full Payment | L3: 2894.05 | N3: {=XLOOKUP($B3, XLOOKUP("Tracking Number", Orders!$1:$1, Orders!$A:$AAA), XLOOKUP("Courier Fee", Orders!$1:$1, Orders!$A:$AAA), "Not Found")} -> 254.95 | O3: =E3*4% -> 10.198 | P3: =SUM(N3:O3) -> 265.148
A4: TR31249 | B4: 25120050023598 | C4: D | D4: 4998 | E4: 578.83 | F4: CPR-RAGFP443199 | G4: 46129 | H4: PostEx | I4: 4998 | J4: ✅ Done | K4: ✅ Full Payment | L4: 4419.17 | N4: {=XLOOKUP($B4, XLOOKUP("Tracking Number", Orders!$1:$1, Orders!$A:$AAA), XLOOKUP("Courier Fee", Orders!$1:$1, Orders!$A:$AAA), "Not Found")} -> 578.83 | O4: =E4*4% -> 23.1532 | P4: =SUM(N4:O4) -> 601.9832
A5: TR31229 | B5: 24120050023592 | C5: D | D5: 6299 | E5: 518.01 | F5: CPR-RAGFP443199 | G5: 46129 | H5: PostEx | I5: 6299 | J5: ✅ Done | K5: ✅ Full Payment | L5: 5780.99 | N5: {=XLOOKUP($B5, XLOOKUP("Tracking Number", Orders!$1:$1, Orders!$A:$AAA), XLOOKUP("Courier Fee", Orders!$1:$1, Orders!$A:$AAA), "Not Found")} -> 518.01 | O5: =E5*4% -> 20.7204 | P5: =SUM(N5:O5) -> 538.7304
A6: TR31227 | B6: 24120050023593 | C6: D | D6: 4997 | E6: 465.93 | F6: CPR-RAGFP443199 | G6: 46129 | H6: PostEx | I6: 4997 | J6: ✅ Done | K6: ✅ Full Payment | L6: 4531.07 | N6: {=XLOOKUP($B6, XLOOKUP("Tracking Number", Orders!$1:$1, Orders!$A:$AAA), XLOOKUP("Courier Fee", Orders!$1:$1, Orders!$A:$AAA), "Not Found")} -> 465.93 | O6: =E6*4% -> 18.6372 | P6: =SUM(N6:O6) -> 484.5672
A7: TR31223 | B7: 26120050023565 | C7: D | D7: 2249 | E7: 218.95 | F7: CPR-RAGFP443199 | G7: 46129 | H7: PostEx | I7: 2249 | J7: ✅ Done | K7: ✅ Full Payment | L7: 2030.05 | N7: {=XLOOKUP($B7, XLOOKUP("Tracking Number", Orders!$1:$1, Orders!$A:$AAA), XLOOKUP("Courier Fee", Orders!$1:$1, Orders!$A:$AAA), "Not Found")} -> 218.95 | O7: =E7*4% -> 8.758 | P7: =SUM(N7:O7) -> 227.708
A8: TR31220 | B8: 27120050023569 | C8: D | D8: 3397 | E8: 264.87 | F8: CPR-RAGFP443199 | G8: 46129 | H8: PostEx | I8: 3397 | J8: ✅ Done | K8: ✅ Full Payment | L8: 3132.13 | N8: {=XLOOKUP($B8, XLOOKUP("Tracking Number", Orders!$1:$1, Orders!$A:$AAA), XLOOKUP("Courier Fee", Orders!$1:$1, Orders!$A:$AAA), "Not Found")} -> 264.87 | O8: =E8*4% -> 10.5948 | P8: =SUM(N8:O8) -> 275.4648
A9: TR31219 | B9: 26120050023566 | C9: D | D9: 1949 | E9: 319.82 | F9: CPR-RAGFP443199 | G9: 46129 | H9: PostEx | I9: 1949 | J9: ✅ Done | K9: ✅ Full Payment | L9: 1629.18 | N9: {=XLOOKUP($B9, XLOOKUP("Tracking Number", Orders!$1:$1, Orders!$A:$AAA), XLOOKUP("Courier Fee", Orders!$1:$1, Orders!$A:$AAA), "Not Found")} -> 319.82 | O9: =E9*4% -> 12.7928 | P9: =SUM(N9:O9) -> 332.6128
A10: TR31217 | B10: 24120050023567 | C10: D | D10: 1949 | E10: 206.95 | F10: CPR-RAGFP443199 | G10: 46129 | H10: PostEx | I10: 1949 | J10: ✅ Done | K10: ✅ Full Payment | L10: 1742.05 | N10: {=XLOOKUP($B10, XLOOKUP("Tracking Number", Orders!$1:$1, Orders!$A:$AAA), XLOOKUP("Courier Fee", Orders!$1:$1, Orders!$A:$AAA), "Not Found")} -> 206.95 | O10: =E10*4% -> 8.278 | P10: =SUM(N10:O10) -> 215.228
A11: TR31213 | B11: 25120050023570 | C11: D | D11: 2098 | E11: 325.78 | F11: CPR-RAGFP443199 | G11: 46129 | H11: PostEx | I11: 2098 | J11: ✅ Done | K11: ✅ Full Payment | L11: 1772.22 | N11: {=XLOOKUP($B11, XLOOKUP("Tracking Number", Orders!$1:$1, Orders!$A:$AAA), XLOOKUP("Courier Fee", Orders!$1:$1, Orders!$A:$AAA), "Not Found")} -> 325.78 | O11: =E11*4% -> 13.0312 | P11: =SUM(N11:O11) -> 338.8112
A12: TR31204 | B12: 23120050023579 | C12: D | D12: 2049 | E12: 210.95 | F12: CPR-RAGFP443199 | G12: 46129 | H12: PostEx | I12: 2049 | J12: ✅ Done | K12: ✅ Full Payment | L12: 1838.05 | N12: {=XLOOKUP($B12, XLOOKUP("Tracking Number", Orders!$1:$1, Orders!$A:$AAA), XLOOKUP("Courier Fee", Orders!$1:$1, Orders!$A:$AAA), "Not Found")} -> 210.95 | O12: =E12*4% -> 8.438 | P12: =SUM(N12:O12) -> 219.388
A13: TR31201 | B13: 24120050023580 | C13: D | D13: 2999 | E13: 377.94 | F13: CPR-RAGFP443199 | G13: 46129 | H13: PostEx | I13: 2999 | J13: ✅ Done | K13: ✅ Full Payment | L13: 2621.06 | N13: {=XLOOKUP($B13, XLOOKUP("Tracking Number", Orders!$1:$1, Orders!$A:$AAA), XLOOKUP("Courier Fee", Orders!$1:$1, Orders!$A:$AAA), "Not Found")} -> 377.94 | O13: =E13*4% -> 15.1176 | P13: =SUM(N13:O13) -> 393.0576
A14: TR31198 | B14: 21120050023523 | C14: D | D14: 2099 | E14: 341.94 | F14: CPR-RAGFP443199 | G14: 46129 | H14: PostEx | I14: 2099 | J14: ✅ Done | K14: ✅ Full Payment | L14: 1757.06 | N14: {=XLOOKUP($B14, XLOOKUP("Tracking Number", Orders!$1:$1, Orders!$A:$AAA), XLOOKUP("Courier Fee", Orders!$1:$1, Orders!$A:$AAA), "Not Found")} -> 341.94 | O14: =E14*4% -> 13.6776 | P14: =SUM(N14:O14) -> 355.6176
... A103: TR29985 | B103: 23120050023015 | C103: R | D103: 0 | E103: 235.71 | F103: CPR-RAGFP443199 | G103: 46129 | H103: PostEx | I103: 249 | J103: ✅ Done | K103: Return Fee Recorded | L103: -235.71 | N103: {=XLOOKUP($B103, XLOOKUP("Tracking Number", Orders!$1:$1, Orders!$A:$AAA), XLOOKUP("Courier Fee", Orders!$1:$1, Orders!$A:$AAA), "Not Found")} -> 235.71 | O103: =E103*4% -> 9.4284 | P103: =SUM(N103:O103) -> 245.1384
A104: TR31248 | B104: 28120050023589 | C104: D | D104: 0 | E104: 257.98 | F104: CPR-RAGFP443199 | G104: 46129 | H104: PostEx | I104: 2520 | J104: ❌ API Error | K104: Request failed for https://041839-3.myshopify.com returned code 422. Truncated server response: {"errors":{"amount":["must be greater than zero for capture transactions"]}} (use muteHttpExceptions option to examine full response) | N104: {=XLOOKUP($B104, XLOOKUP("Tracking Number", Orders!$1:$1, Orders!$A:$AAA), XLOOKUP("Courier Fee", Orders!$1:$1, Orders!$A:$AAA), "Not Found")} | O104: =E104*4% -> 10.3192 | P104: =SUM(N104:O104) -> 10.3192
A105: TR31246 | B105: 25120050023590 | C105: D | D105: 0 | E105: 241.86 | F105: CPR-RAGFP443199 | G105: 46129 | H105: PostEx | I105: 1665 | J105: ❌ API Error | K105: Request failed for https://041839-3.myshopify.com returned code 422. Truncated server response: {"errors":{"amount":["must be greater than zero for capture transactions"]}} (use muteHttpExceptions option to examine full response) | N105: {=XLOOKUP($B105, XLOOKUP("Tracking Number", Orders!$1:$1, Orders!$A:$AAA), XLOOKUP("Courier Fee", Orders!$1:$1, Orders!$A:$AAA), "Not Found")} | O105: =E105*4% -> 9.6744 | P105: =SUM(N105:O105) -> 9.6744
A106: TR31226 | B106: 23120050023577 | C106: D | D106: 0 | E106: 257.98 | F106: CPR-RAGFP443199 | G106: 46129 | H106: PostEx | I106: 3399 | J106: ❌ API Error | K106: Request failed for https://041839-3.myshopify.com returned code 422. Truncated server response: {"errors":{"amount":["must be greater than zero for capture transactions"]}} (use muteHttpExceptions option to examine full response) | N106: {=XLOOKUP($B106, XLOOKUP("Tracking Number", Orders!$1:$1, Orders!$A:$AAA), XLOOKUP("Courier Fee", Orders!$1:$1, Orders!$A:$AAA), "Not Found")} | O106: =E106*4% -> 10.3192 | P106: =SUM(N106:O106) -> 10.3192
A107: TR31202 | B107: 25120050023541 | C107: D | D107: 0 | E107: 241.86 | F107: CPR-RAGFP443199 | G107: 46129 | H107: PostEx | I107: 1499 | J107: ❌ API Error | K107: Request failed for https://041839-3.myshopify.com returned code 422. Truncated server response: {"errors":{"amount":["must be greater than zero for capture transactions"]}} (use muteHttpExceptions option to examine full response) | N107: {=XLOOKUP($B107, XLOOKUP("Tracking Number", Orders!$1:$1, Orders!$A:$AAA), XLOOKUP("Courier Fee", Orders!$1:$1, Orders!$A:$AAA), "Not Found")} | O107: =E107*4% -> 9.6744 | P107: =SUM(N107:O107) -> 9.6744
A108: TR31005 | B108: 24120050023415 | C108: D | D108: 0 | E108: 257.98 | F108: CPR-RAGFP443199 | G108: 46129 | H108: PostEx | I108: 3397 | J108: ❌ API Error | K108: Request failed for https://041839-3.myshopify.com returned code 422. Truncated server response: {"errors":{"amount":["must be greater than zero for capture transactions"]}} (use muteHttpExceptions option to examine full response) | N108: {=XLOOKUP($B108, XLOOKUP("Tracking Number", Orders!$1:$1, Orders!$A:$AAA), XLOOKUP("Courier Fee", Orders!$1:$1, Orders!$A:$AAA), "Not Found")} | O108: =E108*4% -> 10.3192 | P108: =SUM(N108:O108) -> 10.3192
A109: TR31203 | B109: 27120050023547 | C109: D | D109: 0 | E109: 128.99 | F109: CPR-RAGFP443199 | G109: 46129 | H109: PostEx | J109: 🛑 Skipped | K109: Already Paid | N109: {=XLOOKUP($B109, XLOOKUP("Tracking Number", Orders!$1:$1, Orders!$A:$AAA), XLOOKUP("Courier Fee", Orders!$1:$1, Orders!$A:$AAA), "Not Found")} | O109: =E109*4% -> 5.1596 | P109: =SUM(N109:O109) -> 5.1596
N110: {=XLOOKUP($B110, XLOOKUP("Tracking Number", Orders!$1:$1, Orders!$A:$AAA), XLOOKUP("Courier Fee", Orders!$1:$1, Orders!$A:$AAA), "Not Found")} -> Not Found | O110: =E110*4% -> 0 | P110: =SUM(N110:O110) -> 0
N111: {=XLOOKUP($B111, XLOOKUP("Tracking Number", Orders!$1:$1, Orders!$A:$AAA), XLOOKUP("Courier Fee", Orders!$1:$1, Orders!$A:$AAA), "Not Found")} -> Not Found | O111: =E111*4% -> 0 | P111: =SUM(N111:O111) -> 0
N112: {=XLOOKUP($B112, XLOOKUP("Tracking Number", Orders!$1:$1, Orders!$A:$AAA), XLOOKUP("Courier Fee", Orders!$1:$1, Orders!$A:$AAA), "Not Found")} -> Not Found | O112: =E112*4% -> 0 | P112: =SUM(N112:O112) -> 0
N113: {=XLOOKUP($B113, XLOOKUP("Tracking Number", Orders!$1:$1, Orders!$A:$AAA), XLOOKUP("Courier Fee", Orders!$1:$1, Orders!$A:$AAA), "Not Found")} -> Not Found | O113: =E113*4% -> 0 | P113: =SUM(N113:O113) -> 0
N114: {=XLOOKUP($B114, XLOOKUP("Tracking Number", Orders!$1:$1, Orders!$A:$AAA), XLOOKUP("Courier Fee", Orders!$1:$1, Orders!$A:$AAA), "Not Found")} -> Not Found | O114: =E114*4% -> 0 | P114: =SUM(N114:O114) -> 0
N115: {=XLOOKUP($B115, XLOOKUP("Tracking Number", Orders!$1:$1, Orders!$A:$AAA), XLOOKUP("Courier Fee", Orders!$1:$1, Orders!$A:$AAA), "Not Found")} -> Not Found | O115: =E115*4% -> 0 | P115: =SUM(N115:O115) -> 0
N116: {=XLOOKUP($B116, XLOOKUP("Tracking Number", Orders!$1:$1, Orders!$A:$AAA), XLOOKUP("Courier Fee", Orders!$1:$1, Orders!$A:$AAA), "Not Found")} -> Not Found | O116: =E116*4% -> 0 | P116: =SUM(N116:O116) -> 0
N117: {=XLOOKUP($B117, XLOOKUP("Tracking Number", Orders!$1:$1, Orders!$A:$AAA), XLOOKUP("Courier Fee", Orders!$1:$1, Orders!$A:$AAA), "Not Found")} -> Not Found | O117: =E117*4% -> 0 | P117: =SUM(N117:O117) -> 0
N118: {=XLOOKUP($B118, XLOOKUP("Tracking Number", Orders!$1:$1, Orders!$A:$AAA), XLOOKUP("Courier Fee", Orders!$1:$1, Orders!$A:$AAA), "Not Found")} -> Not Found | O118: =E118*4% -> 0 | P118: =SUM(N118:O118) -> 0
N119: {=XLOOKUP($B119, XLOOKUP("Tracking Number", Orders!$1:$1, Orders!$A:$AAA), XLOOKUP("Courier Fee", Orders!$1:$1, Orders!$A:$AAA), "Not Found")} -> Not Found | O119: =E119*4% -> 0 | P119: =SUM(N119:O119) -> 0
N120: {=XLOOKUP($B120, XLOOKUP("Tracking Number", Orders!$1:$1, Orders!$A:$AAA), XLOOKUP("Courier Fee", Orders!$1:$1, Orders!$A:$AAA), "Not Found")} -> Not Found | O120: =E120*4% -> 0 | P120: =SUM(N120:O120) -> 0
N121: {=XLOOKUP($B121, XLOOKUP("Tracking Number", Orders!$1:$1, Orders!$A:$AAA), XLOOKUP("Courier Fee", Orders!$1:$1, Orders!$A:$AAA), "Not Found")} -> Not Found | O121: =E121*4% -> 0 | P121: =SUM(N121:O121) -> 0
... N705: {=XLOOKUP($B705, XLOOKUP("Tracking Number", Orders!$1:$1, Orders!$A:$AAA), XLOOKUP("Courier Fee", Orders!$1:$1, Orders!$A:$AAA), "Not Found")} -> Not Found | O705: =E705*4% -> 0 | P705: =SUM(N705:O705) -> 0

Sheet Monitor Stuck Parcels
A1: Tracking | B1: Customer | C1: Status | D1: ⏳ Days Stuck | E1: Note | F1: Price | G1: Product | H1: Last Date | I1: ACTION
A2: 23120050020579 | B2: Nadeem Abbasi | C2: returned | D2: 109 Days | E2: complain marked PostEx | Product MIssing | details Shared | | ↩️ Return Charged: 2026-01-02 | Fee: 200.1 | F2: 2748 | G2: Imported Scoba Executive Nik Tro - M / Silver Grey (x1) | H2: 46022.757
A3: 20120050022641 | B3: Muzammil Sabir | C3: attempted | D3: 5 Days | E3: confirm | F3: 3348 | G3: Multi ref PUM-A - M / White (x1), Multi ref PUM-A - M / Black (x1) | H3: 46126.081
A4: 29120050023561 | B4: Junaid Babu | C4: un-assigned by me | D4: 3 Days | E4: not ans / not confirmed | F4: 5247 | G4: Embossed NIK-E - XL / Black (x1), Embossed NIK-E - XL / White (x1), Basic Branded Adi Trouser - L / Black (x1) | H4: 46128.081
A5: 29120050023007 | B5: Dr Junaid Junaid | C5: un-assigned by me | D5: 9 Days | E5: confirm | F5: 3348 | G5: Multi ref PUM-A - M / White (x1), Multi ref PUM-A - M / Black (x1) | H5: 46122.081
A6: 27120050023005 | B6: Sohrab Qalandari | C6: un-assigned by me | D6: 9 Days | E6: confirm | F6: 3348 | G6: Multi ref PUM-A - M / White (x1), Multi ref PUM-A - M / Black (x1) | H6: 46122.081
A7: LE7532033190 | B7: Ali Ahmad | C7: shipper advice | D7: 2 Days | E7: lcs Nankana sahib | F7: 3348 | G7: ADI Multi Ref Stripes - XL / White (x1), ADI Multi Ref Stripes - L / Black (x1) | H7: 46129.083
A8: 22120050023112 | B8: Faro Khan | C8: un-assigned by me | D8: 9 Days | E8: confirm | F8: 2199 | G8: Multi ref PUM-A - M / White (x1) | H8: 46122.081
A9: 24120050023097 | B9: Waseem Aslam | C9: un-assigned by me | D9: 9 Days | E9: confirm | F9: 3348 | G9: Multi ref PUM-A - L / White (x1), Multi ref PUM-A - L / Black (x1) | H9: 46122.081
A10: 25120050023000 | B10: adeel raja | C10: un-assigned by me | D10: 9 Days | E10: open to allow | F10: 3348 | G10: Multi ref PUM-A - M / White (x1), Multi ref PUM-A - M / Black (x1) | H10: 46122.081
A11: 25120050023040 | B11: Afnan Saeed | C11: un-assigned by me | D11: 9 Days | E11: confirm | F11: 3348 | G11: Multi ref PUM-A - M / White (x1), Multi ref PUM-A - M / Black (x1) | H11: 46122.081
A12: 22120050023206 | B12: Hammad Arif | C12: en-route to lahore warehouse | D12: 3 Days | E12: not ans confirm | F12: 3348 | G12: ADI Multi Ref Stripes - M / White (x1), ADI Multi Ref Stripes - M / Black (x1) | H12: 46128.081
A13: 20120050023204 | B13: Aqeel Ali | C13: un-assigned by me | D13: 9 Days | E13: confirm | F13: 3348 | G13: Multi ref PUM-A - M / White (x1), Multi ref PUM-A - M / Black (x1) | H13: 46122.081
A14: LE7530384423 | B14: Waris iqbal Iqbal | C14: in transit | D14: 5 Days | E14: khaplu lcs | F14: 3348 | G14: Multi ref PUM-A - 3XL / White (x1), Multi ref PUM-A - 3XL / Black (x1) | H14: 46126.083
A15: 27120050023032 | B15: Awais Aslam | C15: returned | D15: 10 Days | E15: (rehman issue) allow to oepn rider open kerna nahi da raha | ↩️ Return Charged: 2026-04-10 | Ref: CPR-XWOR8962608 | Fee: 552.45 | F15: 11447 | G15: Basic Branded Adi Trouser - XL / Black (x1), Adi- Hoodie - XL / Black (x1), ADI Multi Ref Stripes - XL / White (x1), ADI Multi Ref Stripes - XL / Black (x1), ADI - TriStrip-Tracksuit Winter - XL / Gray (x1) | H15: 46121.081
A16: 22120050023188 | B16: Zekash Ahmad Allow to Open | C16: un-assigned by me | D16: 9 Days | E16: confirm | F16: 3348 | G16: Multi ref PUM-A - L / White (x1), Multi ref PUM-A - L / Black (x1) | H16: 46122.081
A17: 22120050023186 | B17: Muhammad Tayyab Abbasi | C17: un-assigned by me | D17: 9 Days | E17: confirm | F17: 3348 | G17: Multi ref PUM-A - L / White (x1), Multi ref PUM-A - L / Black (x1) | H17: 46122.081
A18: 24120050023236 | B18: Omer Mehmood Ch Mehmood Son’s | C18: un-assigned by me | D18: 9 Days | E18: confirm | F18: 2199 | G18: Multi ref PUM-A - L / White (x1) | H18: 46122.081
A19: 29120050023181 | B19: Sohaib Nasir | C19: un-assigned by me | D19: 9 Days | F19: 3399 | G19: Multi ref PUM-A - L / White (x1), ADI - EMBOSSED LOGO - L / Olive( Commando Green) (x1) | H19: 46122.081
A20: 29120050023178 | B20: Muhammad Usman Muhammad | C20: un-assigned by me | D20: 9 Days | E20: confirm | F20: 2199 | G20: Multi ref PUM-A - M / White (x1) | H20: 46122.081
A21: 29120050023235 | B21: Tauqeer Akbar | C21: un-assigned by me | D21: 9 Days | E21: confirm | F21: 6249 | G21: Multi ref PUM-A - L / White (x1), ADI - EMBOSSED LOGO - L / Black (x1), Tipping Crew - L / White (x1), Tipping Crew - L / Black (x1) | H21: 46122.081
A22: 23120050023128 | B22: Saima Butt | C22: un-assigned by me | D22: 9 Days | F22: 3348 | G22: Multi ref PUM-A - L / White (x1), Multi ref PUM-A - L / Black (x1) | H22: 46122.081
A23: LE7530384557 | B23: Nabeel Ch Ch | C23: shipper advice | D23: 3 Days | E23: confirm ( call when arrived at Station ) office sa recive ker la ga parcel | F23: 1848 | G23: ADI-Trouser Tri strip - L / Black (x1) | H23: 46128.083
A24: 21120050023303 | B24: Zubair Ahmad | C24: un-assigned by me | D24: 9 Days | E24: confirm | F24: 1449 | G24: ADI - EMBOSSED LOGO - M / Black (x1) | H24: 46122.081
A25: 25120050023211 | B25: Zunair Munir | C25: un-assigned by me | D25: 9 Days | E25: confirm postex | F25: 3348 | G25: Multi ref PUM-A - L / White (x1), Multi ref PUM-A - L / Black (x1) | H25: 46122.081
A26: 24120050023261 | B26: asad Habib | C26: un-assigned by me | D26: 9 Days | E26: confirm on call | F26: 3348 | G26: Multi ref PUM-A - M / White (x1), Multi ref PUM-A - M / Black (x1) | H26: 46122.081
A27: 24120050023260 | B27: Abubakar Ch | C27: un-assigned by me | D27: 9 Days | F27: 3348 | G27: Multi ref PUM-A - M / White (x1), Multi ref PUM-A - M / Black (x1) | H27: 46122.081
A28: 21120050023560 | B28: Ismail Khan | C28: un-assigned by me | D28: 3 Days | E28: confirm | F28: 4098 | G28: Adi Winter Trouser - M / Black (x1), Embossed NIK-E - M / Black (x1) | H28: 46128.081
A29: 21120050023256 | B29: javed iqbal | C29: un-assigned by me | D29: 9 Days | E29: confirm | F29: 3348 | G29: Multi ref PUM-A - L / White (x1), Multi ref PUM-A - L / Black (x1) | H29: 46122.081
A30: 23120050023255 | B30: Ali Raza | C30: un-assigned by me | D30: 9 Days | E30: confirm | F30: 2199 | G30: Multi ref PUM-A - M / White (x1) | H30: 46122.081
A31: 28120050023299 | B31: Irum Bukhari | C31: un-assigned by me | D31: 9 Days | E31: confirm | F31: 3348 | G31: Multi ref PUM-A - M / White (x1), Multi ref PUM-A - M / Black (x1) | H31: 46122.081
A32: 29120050023250 | B32: Syed Aashir Abbas | C32: un-assigned by me | D32: 9 Days | E32: confirm | F32: 2199 | G32: Multi ref PUM-A - M / White (x1) | H32: 46122.081
A33: 28120050023279 | B33: Athwani Akash | C33: un-assigned by me | D33: 9 Days | E33: confirm | F33: 3348 | G33: Multi ref PUM-A - M / White (x1), Multi ref PUM-A - M / Black (x1) | H33: 46122.081
A34: 21120050023247 | B34: Inam Khan | C34: un-assigned by me | D34: 9 Days | E34: confirm | F34: 3348 | G34: Multi ref PUM-A - M / White (x1), Multi ref PUM-A - M / Black (x1) | H34: 46122.081
A35: 29120050023242 | B35: danish danish | C35: un-assigned by me | D35: 9 Days | E35: in wp whatsup | F35: 3698 | G35: ADI-Trouser Tri strip - L / Black (x1), Multi ref PUM-A - L / White (x1) | H35: 46122.081
A36: 173012419967 | B36: Amir Ilyas | C36: delivery unsuccessful | D36: 5 Days | E36: TCS | F36: 3348 | G36: ADI Multi Ref Stripes - 4XL / White (x1), ADI Multi Ref Stripes - 4XL / Black (x1) | H36: 46126.083
A37: 27120050023293 | B37: Muhammad Asim | C37: un-assigned by me | D37: 9 Days | F37: 3348 | G37: Multi ref PUM-A - L / White (x1), Multi ref PUM-A - L / Black (x1) | H37: 46122.081
A38: 22120050023286 | B38: Osaid Khaled | C38: un-assigned by me | D38: 9 Days | E38: confirm | F38: 3398 | G38: Multi ref PUM-A - M / White (x1), Multi ref PUM-A - M / Black (x1) | H38: 46122.081
A39: 20120050023340 | B39: Yasir Wasim | C39: un-assigned by me | D39: 9 Days | E39: confirm | F39: 3398 | G39: Multi ref PUM-A - L / White (x1), Multi ref PUM-A - L / Black (x1) | H39: 46122.081
A40: 23120050023339 | B40: Shah Zeb | C40: un-assigned by me | D40: 9 Days | E40: confirm | F40: 4199 | G40: Multi ref PUM-A - M / Black (x1), Multi ref PUM-A - M / White (x1) | H40: 46122.081
...

Sheet SEARCH_TOOL
A1: 📅 Preset | B1: 📆 Start | C1: 🏁 End | D1: 🏷️ Status Filter | E1: 🔑 Keyword | F1: 🗂️ Sort By | G1: ⭐ Load View | H1: 🔍 Found: 8 Orders 💰 Sum: Rs 30,085 | J1: ✅ Delivered: 0 | 🔄 Returned: 8 | ⏳ Pending: 0 | L1: =IFERROR(__xludf.DUMMYFUNCTION("SPARKLINE({0,8,0}, {""charttype"",""bar""; ""color1"",""#d9ead3""; ""color2"",""#f4cccc""; ""color3"",""#fce5cd""})"),"")
A2: All Time | B2: 46109 | C2: 46109 | D2: Returned, Returned to Shipper | F2: Default
A3: 🔄 RUN SEARCH ➡️ | B3: FALSE | C3: 💾 SAVE VIEW ➡️ | D3: FALSE | E3: 🗑️ DELETE VIEW ➡️ | F3: FALSE | G3: 🧹 RESET BOARD ➡️ | H3: FALSE
A4: Order ID | B4: Date | C4: Customer Name | D4: Phone | E4: City | F4: Price | G4: Paid Amount | H4: Pending Balance | I4: Delivery Status | J4: Courier | K4: Tracking Number | L4: notes | M4: COST
A5: =HYPERLINK("https://admin.shopify.com/store/041839-3/orders/6804722188547", "🛍️ 6804722188547") -> 🛍️ 6804722188547 | B5: 46008 | C5: Nadeem Abbasi | D5: =HYPERLINK("https://wa.me/923239699795?text=Hi%2C%20this%20is%20TracePK!%20%F0%9F%8C%9F%20Confirming%20your%20order%20%236804722188547%20for%20Rs%202748.%20Please%20reply%20'YES'%20to%20dispatch.", "💬 3239699795") -> 💬 3239699795 | E5: Murree | F5: 2748 | G5: 0 | H5: 2748 | I5: Returned | J5: Postex | K5: =HYPERLINK("https://merchant.postex.pk/track/23120050020579", "🚚 23120050020579") -> 🚚 23120050020579 | L5: complain marked PostEx | Product MIssing | details Shared | | ↩️ Return Charged: 2026-01-02 | Fee: 200.1 | M5: 1400
A6: =HYPERLINK("https://admin.shopify.com/store/041839-3/orders/6959736619267", "🛍️ 6959736619267") -> 🛍️ 6959736619267 | B6: 46101 | C6: Raza Abbas | D6: =HYPERLINK("https://wa.me/923093895214?text=Hi%2C%20this%20is%20TracePK!%20%F0%9F%8C%9F%20Confirming%20your%20order%20%236959736619267%20for%20Rs%201499.%20Please%20reply%20'YES'%20to%20dispatch.", "💬 3093895214") -> 💬 3093895214 | E6: Matairi | F6: 1499 | H6: 1499 | I6: Returned | J6: PostEx | K6: =HYPERLINK("https://merchant.postex.pk/track/29120050023334", "🚚 29120050023334") -> 🚚 29120050023334 | L6: confirm | M6: 750
A7: =HYPERLINK("https://admin.shopify.com/store/041839-3/orders/6972048507139", "🛍️ 6972048507139") -> 🛍️ 6972048507139 | B7: 46108 | C7: Awais Aslam | D7: =HYPERLINK("https://wa.me/923352360116?text=Hi%2C%20this%20is%20TracePK!%20%F0%9F%8C%9F%20Confirming%20your%20order%20%236972048507139%20for%20Rs%2011447.%20Please%20reply%20'YES'%20to%20dispatch.", "💬 3352360116") -> 💬 3352360116 | E7: Rawalpindi | F7: 11447 | H7: 11447 | I7: Returned | J7: PostEx | K7: =HYPERLINK("https://merchant.postex.pk/track/27120050023032", "🚚 27120050023032") -> 🚚 27120050023032 | L7: (rehman issue) allow to oepn rider open kerna nahi da raha | ↩️ Return Charged: 2026-04-10 | Ref: CPR-XWOR8962608 | Fee: 552.45 | M7: 3900
A8: =HYPERLINK("https://admin.shopify.com/store/041839-3/orders/6984277983491", "🛍️ 6984277983491") -> 🛍️ 6984277983491 | B8: 46116 | C8: Zeshan niazi Zeshan niazi | D8: =HYPERLINK("https://wa.me/923254721823?text=Hi%2C%20this%20is%20TracePK!%20%F0%9F%8C%9F%20Confirming%20your%20order%20%236984277983491%20for%20Rs%203149.%20Please%20reply%20'YES'%20to%20dispatch.", "💬 +923254721823") -> 💬 +923254721823 | E8: Lahore | F8: 3149 | H8: 3149 | I8: Returned | J8: PostEx | K8: =HYPERLINK("https://merchant.postex.pk/track/23120050023425", "🚚 23120050023425") -> 🚚 23120050023425 | L8: whatsup | M8: 720
A9: =HYPERLINK("https://admin.shopify.com/store/041839-3/orders/6990662959363", "🛍️ 6990662959363") -> 🛍️ 6990662959363 | B9: 46121 | C9: Jalees Khan | D9: =HYPERLINK("https://wa.me/923047788894?text=Hi%2C%20this%20is%20TracePK!%20%F0%9F%8C%9F%20Confirming%20your%20order%20%236990662959363%20for%20Rs%202797.%20Please%20reply%20'YES'%20to%20dispatch.", "💬 3047788894") -> 💬 3047788894 | E9: Mailsi | F9: 2797 | H9: 2797 | I9: Returned | J9: PostEx | K9: =HYPERLINK("https://merchant.postex.pk/track/20120050023404", "🚚 20120050023404") -> 🚚 20120050023404 | L9: consignee want open parcel | M9: 1100
A10: =HYPERLINK("https://admin.shopify.com/store/041839-3/orders/6991776973059", "🛍️ 6991776973059") -> 🛍️ 6991776973059 | B10: 46121 | C10: Qasim Jutt | D10: =HYPERLINK("https://wa.me/923007213980?text=Hi%2C%20this%20is%20TracePK!%20%F0%9F%8C%9F%20Confirming%20your%20order%20%236991776973059%20for%20Rs%203397.%20Please%20reply%20'YES'%20to%20dispatch.", "💬 3007213980") -> 💬 3007213980 | E10: Faisalabad | F10: 3397 | H10: 3397 | I10: Returned | J10: PostEx | K10: =HYPERLINK("https://merchant.postex.pk/track/20120050023478", "🚚 20120050023478") -> 🚚 20120050023478 | L10: not ans confirm | M10: 720
A11: =HYPERLINK("https://admin.shopify.com/store/041839-3/orders/6993094312195", "🛍️ 6993094312195") -> 🛍️ 6993094312195 | B11: 46122 | C11: Hassan Raza | D11: =HYPERLINK("https://wa.me/923044495171?text=Hi%2C%20this%20is%20TracePK!%20%F0%9F%8C%9F%20Confirming%20your%20order%20%236993094312195%20for%20Rs%201949.%20Please%20reply%20'YES'%20to%20dispatch.", "💬 3044495171") -> 💬 3044495171 | E11: Bhera | F11: 1949 | H11: 1949 | I11: Returned | J11: PostEx | K11: =HYPERLINK("https://merchant.postex.pk/track/21120050023499", "🚚 21120050023499") -> 🚚 21120050023499 | L11: confir koi nahi aya | M11: 550
A12: =HYPERLINK("https://admin.shopify.com/store/041839-3/orders/6994171855107", "🛍️ 6994171855107") -> 🛍️ 6994171855107 | B12: 46123 | C12: Arslan Nawaz | D12: =HYPERLINK("https://wa.me/923016870627?text=Hi%2C%20this%20is%20TracePK!%20%F0%9F%8C%9F%20Confirming%20your%20order%20%236994171855107%20for%20Rs%203099.%20Please%20reply%20'YES'%20to%20dispatch.", "💬 3016870627") -> 💬 3016870627 | E12: Lahore | F12: 3099 | H12: 3099 | I12: Returned | J12: PostEx | K12: =HYPERLINK("https://merchant.postex.pk/track/28120050023597", "🚚 28120050023597") -> 🚚 28120050023597 | L12: confirm on wp open to allow | M12: 1100

Sheet PNL
C1: IN | D1: IN | F1: OUT | G1: OUT | H1: OUT | I1: OUT | J1: IN | K1: OUT | M1: OUT | N1: OUT | O1: OUT | P1: IN | Q1: OUT | R1: OUT | S1: IN | T1: OUT | W1: IN
A2: Averages | G2: =AVERAGE(G5:G35) -> 3161.322 | J2: =AVERAGE(J5:J35) -> 28605.704 | N2: =AVERAGE(N5:N35) -> 10808.001 | O2: =AVERAGE(O5:O35) -> 70.827636 | S2: =AVERAGE(S5:S35) -> 40.741935 | T2: =AVERAGE(T5:T35) -> 5.0967742 | W2: =AVERAGE(W5:W35) -> 35.645161
A3: Totals | B3: =AVERAGE(B5:B35) -> 3138.3367 | C3: =sum(C5:C35) -> 2450024.6 | D3: =SUM(D5:D35) -> 903820 | E3: =AVERAGE(E5:E35) -> 0.36757546 | F3: =SUM(F5:F35) -> 2352023.6 | G3: =SUM(G5:G35) -> 98000.983 | H3: =sum(F5:F35) -> 2352023.6 | I3: =AVERAGE(I5:I35) -> 38.803116 | J3: =sum(J5:J35) -> 886776.81 | K3: =sum(K5:K35) -> 0 | L3: =SUM(L5:L35) -> 319000.98 | M3: =sum(M5:M35) -> 324379.74 | N3: =sum(N5:N35) -> 335048.03 | O3: =AVERAGE(O5:O35) -> 70.827636 | P3: =AVERAGE(P5:P35) -> 4.7325904 | Q3: =AVERAGE(Q5:Q35) -> 747.43677 | R3: =AVERAGE(R5:R35) -> 851.58616 | S3: =sum(S5:S35) -> 1263 | T3: =sum(T5:T35) -> 158 | U3: =AVERAGE(U5:U35) -> 0.12373487 | V3: =sum(V5:V35) -> 0 | W3: =sum(W5:W35) -> 1105 | X3: =AVERAGE(X5:X35) -> 0.87626513 | Y3: =sum(Y5:Y35) -> 786 | Z3: =sum(Z5:Z35) -> 318 | AA3: =SUM(AA5:AA35) -> 1 | AB3: =sum(AB5:AB35) -> 1 | AD3: =SUM(AD5:AD35) -> 2447525.6 | AE3: =sum(AE5:AE35) -> 2499
A4: Dates | B4: AOV | C4: Delivered sale | D4: CGS | E4: CGS % | F4: -4% tax | G4: TAX Paid | H4: Gross Profit | I4: Mar % | J4: Marketing 10% tax | K4: Tiktok marketing | L4: est courier (200 x total parcel dispatch | M4: Actual exp + tax | N4: PNL (Day vise) | O4: Del% | P4: ROAS(meta) | Q4: CPA AVG (mar/landed orders) | R4: Net CPA AVG(after cancelations) | S4: Landed orders | T4: Cancelations | U4: cal % | V4: Pending | W4: Total Dipatched | X4: Dis % | Y4: Delivered | Z4: Restocked | AA4: Intransit | AB4: Fake Return | AC4: without tracking id | AD4: payment paid | AE4: Diff correction | AF4: Refrance Number that have diff | AG4: Unsorted Tracking IDs | AH4: Delivered (payment pending)
A5: 45992 | B5: =C5/Y5 -> 2773.5714 | C5: =SUMIFS(Orders!$H:$H, Orders!$Z:$Z, $A5, Orders!$M:$M, "Delivered") -> 77660 | D5: =SUMIFS(Orders!$Q:$Q, Orders!$Z:$Z, $A5, Orders!$M:$M, "Delivered") -> 26870 | E5: =D5/C5 -> 0.34599536 | F5: =C5-(C5*4/100) -> 74553.6 | G5: =C5-F5 -> 3106.4 | H5: =C5-D5 -> 50790 | I5: =IFERROR(J5/C5, 0)*100 -> 48.799897 | J5: 37898 | L5: =(200*W5)+C5*4% -> 11506.4 | M5: =SUMIFS(Orders!$W:$W, Orders!$Z:$Z, $A5) -> 11400 | N5: =H5-J5-K5-M5 -> 1492 | O5: =Y5/W5*100 -> 66.666667 | P5: 3.8442817 | Q5: =J5/S5 -> 823.86957 | R5: =J5/W5 -> 902.33333 | S5: =COUNTIFS(Orders!$Z:$Z, $A5) -> 46 | T5: =COUNTIFS(Orders!$Z:$Z, $A5, Orders!$M:$M, "Cancelled") -> 4 | U5: =T5/S5 -> 0.086956522 | V5: =COUNTIFS(Orders!$Z:$Z, $A5, Orders!$M:$M, "pending") -> 0 | W5: =S5-T5 -> 42 | X5: =W5/S5 -> 0.91304348 | Y5: =COUNTIFS(Orders!$Z:$Z, $A5, Orders!$M:$M, "Delivered") -> 28 | Z5: =COUNTIFS(Orders!$Z:$Z, $A5, Orders!$M:$M, "Return Received") -> 14 | AA5: =W5-Y5-Z5-V5 -> 0 | AB5: {=SUM(COUNTIFS(Orders!$Z:$Z, $A5, Orders!$M:$M, {"Returned","Returned to Shipper"}))} -> 0 | AC5: =COUNTIFS(Orders!$Z:$Z, $A5, Orders!$I:$I, "", Orders!$M:$M, "<>Cancelled") -> 0 | AD5: =SUMIFS(Orders!$U:$U, Orders!$Z:$Z, $A5, Orders!$M:$M, "Delivered") -> 75161 | AE5: =C5-AD5 -> 2499 | AF5: =IFERROR(__xludf.DUMMYFUNCTION("IFERROR(TEXTJOIN("", "", TRUE, FILTER(Orders!$B$2:$B$2517, (TEXT(Orders!$D$2:$D$2517,""d-mmm"")=TEXT($A5,""d-mmm"")) * (ABS(Orders!$H$2:$H$2517 - Orders!$U$2:$U$2517) >= 1) * (Orders!$M$2:$M$2517=""Delivered""))), ""All Balanced"")"),"TR26747") -> TR26747 | AG5: =IFERROR(__xludf.DUMMYFUNCTION("IFERROR(TEXTJOIN("", "", TRUE, FILTER(Orders!$I$2:$I$2517, (Orders!$M$2:$M$2517=""Delivered"") * (Orders!$N$2:$N$2517<>""Paid"") * (Orders!$Z$2:$Z$2517=$A5))), """")"),"23120050019955") -> 23120050019955 | AH5: =COUNTIFS(Orders!$M:$M, "Delivered", Orders!$N:$N, "<>Paid", Orders!$Z:$Z, $A5) -> 0
A6: 45993 | B6: =C6/Y6 -> 3035.9219 | C6: =SUMIFS(Orders!$H:$H, Orders!$Z:$Z, $A6, Orders!$M:$M, "Delivered") -> 194299 | D6: =SUMIFS(Orders!$Q:$Q, Orders!$Z:$Z, $A6, Orders!$M:$M, "Delivered") -> 73085 | E6: =D6/C6 -> 0.37614707 | F6: =C6-(C6*4/100) -> 186527.04 | G6: =C6-F6 -> 7771.96 | H6: =C6-D6 -> 121214 | I6: =IFERROR(J6/C6, 0)*100 -> 17.932274 | J6: 34842.23 | L6: =(200*W6)+C6*4% -> 23171.96 | M6: =SUMIFS(Orders!$W:$W, Orders!$Z:$Z, $A6) -> 23755.2 | N6: =H6-J6-K6-M6 -> 62616.57 | O6: =Y6/W6*100 -> 83.116883 | P6: 4.5074073 | Q6: =J6/S6 -> 419.7859 | R6: =J6/W6 -> 452.49649 | S6: =COUNTIFS(Orders!$Z:$Z, $A6) -> 83 | T6: =COUNTIFS(Orders!$Z:$Z, $A6, Orders!$M:$M, "Cancelled") -> 6 | U6: =T6/S6 -> 0.072289157 | V6: =COUNTIFS(Orders!$Z:$Z, $A6, Orders!$M:$M, "pending") -> 0 | W6: =S6-T6 -> 77 | X6: =W6/S6 -> 0.92771084 | Y6: =COUNTIFS(Orders!$Z:$Z, $A6, Orders!$M:$M, "Delivered") -> 64 | Z6: =COUNTIFS(Orders!$Z:$Z, $A6, Orders!$M:$M, "Return Received") -> 13 | AA6: =W6-Y6-Z6-V6 -> 0 | AB6: {=SUM(COUNTIFS(Orders!$Z:$Z, $A6, Orders!$M:$M, {"Returned","Returned to Shipper"}))} -> 0 | AC6: =COUNTIFS(Orders!$Z:$Z, $A6, Orders!$I:$I, "", Orders!$M:$M, "<>Cancelled") -> 0 | AD6: =SUMIFS(Orders!$U:$U, Orders!$Z:$Z, $A6, Orders!$M:$M, "Delivered") -> 194299 | AE6: =C6-AD6 -> 0 | AF6: =IFERROR(__xludf.DUMMYFUNCTION("IFERROR(TEXTJOIN("", "", TRUE, FILTER(Orders!$B$2:$B$2517, (TEXT(Orders!$D$2:$D$2517,""d-mmm"")=TEXT($A6,""d-mmm"")) * (ABS(Orders!$H$2:$H$2517 - Orders!$U$2:$U$2517) >= 1) * (Orders!$M$2:$M$2517=""Delivered""))), ""All Balanced"")"),"All Balanced") -> All Balanced | AG6: =IFERROR(__xludf.DUMMYFUNCTION("IFERROR(TEXTJOIN("", "", TRUE, FILTER(Orders!$I$2:$I$3000, (Orders!$M$2:$M$3000=""Delivered"") * (Orders!$N$2:$N$3000<>""Paid"") * (Orders!$Z$2:$Z$3000=$A6))), """")"),"") | AH6: =COUNTIFS(Orders!$M:$M, "Delivered", Orders!$N:$N, "<>Paid", Orders!$Z:$Z, $A6) -> 0
A7: 45994 | B7: =C7/Y7 -> 2751.9048 | C7: =SUMIFS(Orders!$H:$H, Orders!$Z:$Z, $A7, Orders!$M:$M, "Delivered") -> 57790 | D7: =SUMIFS(Orders!$Q:$Q, Orders!$Z:$Z, $A7, Orders!$M:$M, "Delivered") -> 22175 | E7: =D7/C7 -> 0.38371691 | F7: =C7-(C7*4/100) -> 55478.4 | G7: =C7-F7 -> 2311.6 | H7: =C7-D7 -> 35615 | I7: =IFERROR(J7/C7, 0)*100 -> 31.433587 | J7: 18165.47 | L7: =(200*W7)+C7*4% -> 8911.6 | M7: =SUMIFS(Orders!$W:$W, Orders!$Z:$Z, $A7) -> 9020.16 | N7: =H7-J7-K7-M7 -> 8429.37 | O7: =Y7/W7*100 -> 63.636364 | P7: 6.8936409 | Q7: =J7/S7 -> 443.06024 | R7: =J7/W7 -> 550.46879 | S7: =COUNTIFS(Orders!$Z:$Z, $A7) -> 41 | T7: =COUNTIFS(Orders!$Z:$Z, $A7, Orders!$M:$M, "Cancelled") -> 8 | U7: =T7/S7 -> 0.19512195 | V7: =COUNTIFS(Orders!$Z:$Z, $A7, Orders!$M:$M, "pending") -> 0 | W7: =S7-T7 -> 33 | X7: =W7/S7 -> 0.80487805 | Y7: =COUNTIFS(Orders!$Z:$Z, $A7, Orders!$M:$M, "Delivered") -> 21 | Z7: =COUNTIFS(Orders!$Z:$Z, $A7, Orders!$M:$M, "Return Received") -> 12 | AA7: =W7-Y7-Z7-V7 -> 0 | AB7: {=SUM(COUNTIFS(Orders!$Z:$Z, $A7, Orders!$M:$M, {"Returned","Returned to Shipper"}))} -> 0 | AC7: =COUNTIFS(Orders!$Z:$Z, $A7, Orders!$I:$I, "", Orders!$M:$M, "<>Cancelled") -> 0 | AD7: =SUMIFS(Orders!$U:$U, Orders!$Z:$Z, $A7, Orders!$M:$M, "Delivered") -> 57790 | AE7: =C7-AD7 -> 0 | AF7: =IFERROR(__xludf.DUMMYFUNCTION("IFERROR(TEXTJOIN("", "", TRUE, FILTER(Orders!$B$2:$B$2517, (TEXT(Orders!$D$2:$D$2517,""d-mmm"")=TEXT($A7,""d-mmm"")) * (ABS(Orders!$H$2:$H$2517 - Orders!$U$2:$U$2517) >= 1) * (Orders!$M$2:$M$2517=""Delivered""))), ""All Balanced"")"),"All Balanced") -> All Balanced | AG7: =IFERROR(__xludf.DUMMYFUNCTION("IFERROR(TEXTJOIN("", "", TRUE, FILTER(Orders!$I$2:$I$3000, (Orders!$M$2:$M$3000=""Delivered"") * (Orders!$N$2:$N$3000<>""Paid"") * (Orders!$Z$2:$Z$3000=$A7))), """")"),"") | AH7: =COUNTIFS(Orders!$M:$M, "Delivered", Orders!$N:$N, "<>Paid", Orders!$Z:$Z, $A7) -> 0
A8: 45995 | B8: =C8/Y8 -> 3473.92 | C8: =SUMIFS(Orders!$H:$H, Orders!$Z:$Z, $A8, Orders!$M:$M, "Delivered") -> 86848 | D8: =SUMIFS(Orders!$Q:$Q, Orders!$Z:$Z, $A8, Orders!$M:$M, "Delivered") -> 32460 | E8: =D8/C8 -> 0.37375645 | F8: =C8-(C8*4/100) -> 83374.08 | G8: =C8-F8 -> 3473.92 | H8: =C8-D8 -> 54388 | I8: =IFERROR(J8/C8, 0)*100 -> 22.991744 | J8: 19967.87 | L8: =(200*W8)+C8*4% -> 11073.92 | M8: =SUMIFS(Orders!$W:$W, Orders!$Z:$Z, $A8) -> 10852 | N8: =H8-J8-K8-M8 -> 23568.13 | O8: =Y8/W8*100 -> 65.789474 | P8: 7.5459121 | Q8: =J8/S8 -> 424.8483 | R8: =J8/W8 -> 525.47026 | S8: =COUNTIFS(Orders!$Z:$Z, $A8) -> 47 | T8: =COUNTIFS(Orders!$Z:$Z, $A8, Orders!$M:$M, "Cancelled") -> 9 | U8: =T8/S8 -> 0.19148936 | V8: =COUNTIFS(Orders!$Z:$Z, $A8, Orders!$M:$M, "pending") -> 0 | W8: =S8-T8 -> 38 | X8: =W8/S8 -> 0.80851064 | Y8: =COUNTIFS(Orders!$Z:$Z, $A8, Orders!$M:$M, "Delivered") -> 25 | Z8: =COUNTIFS(Orders!$Z:$Z, $A8, Orders!$M:$M, "Return Received") -> 13 | AA8: =W8-Y8-Z8-V8 -> 0 | AB8: {=SUM(COUNTIFS(Orders!$Z:$Z, $A8, Orders!$M:$M, {"Returned","Returned to Shipper"}))} -> 0 | AC8: =COUNTIFS(Orders!$Z:$Z, $A8, Orders!$I:$I, "", Orders!$M:$M, "<>Cancelled") -> 0 | AD8: =SUMIFS(Orders!$U:$U, Orders!$Z:$Z, $A8, Orders!$M:$M, "Delivered") -> 86848 | AE8: =C8-AD8 -> 0 | AF8: =IFERROR(__xludf.DUMMYFUNCTION("IFERROR(TEXTJOIN("", "", TRUE, FILTER(Orders!$B$2:$B$2517, (TEXT(Orders!$D$2:$D$2517,""d-mmm"")=TEXT($A8,""d-mmm"")) * (ABS(Orders!$H$2:$H$2517 - Orders!$U$2:$U$2517) >= 1) * (Orders!$M$2:$M$2517=""Delivered""))), ""All Balanced"")"),"All Balanced") -> All Balanced | AG8: =IFERROR(__xludf.DUMMYFUNCTION("IFERROR(TEXTJOIN("", "", TRUE, FILTER(Orders!$I$2:$I$3000, (Orders!$M$2:$M$3000=""Delivered"") * (Orders!$N$2:$N$3000<>""Paid"") * (Orders!$Z$2:$Z$3000=$A8))), """")"),"") | AH8: =COUNTIFS(Orders!$M:$M, "Delivered", Orders!$N:$N, "<>Paid", Orders!$Z:$Z, $A8) -> 0
A9: 45996 | B9: =C9/Y9 -> 2979.2963 | C9: =SUMIFS(Orders!$H:$H, Orders!$Z:$Z, $A9, Orders!$M:$M, "Delivered") -> 80441 | D9: =SUMIFS(Orders!$Q:$Q, Orders!$Z:$Z, $A9, Orders!$M:$M, "Delivered") -> 28195 | E9: =D9/C9 -> 0.35050534 | F9: =C9-(C9*4/100) -> 77223.36 | G9: =C9-F9 -> 3217.64 | H9: =C9-D9 -> 52246 | I9: =IFERROR(J9/C9, 0)*100 -> 35.84943 | J9: 28837.64 | L9: =(200*W9)+C9*4% -> 10217.64 | M9: =SUMIFS(Orders!$W:$W, Orders!$Z:$Z, $A9) -> 10474.88 | N9: =H9-J9-K9-M9 -> 12933.48 | O9: =Y9/W9*100 -> 77.142857 | P9: 4.5993216 | Q9: =J9/S9 -> 758.88526 | R9: =J9/W9 -> 823.93257 | S9: =COUNTIFS(Orders!$Z:$Z, $A9) -> 38 | T9: =COUNTIFS(Orders!$Z:$Z, $A9, Orders!$M:$M, "Cancelled") -> 3 | U9: =T9/S9 -> 0.078947368 | V9: =COUNTIFS(Orders!$Z:$Z, $A9, Orders!$M:$M, "pending") -> 0 | W9: =S9-T9 -> 35 | X9: =W9/S9 -> 0.92105263 | Y9: =COUNTIFS(Orders!$Z:$Z, $A9, Orders!$M:$M, "Delivered") -> 27 | Z9: =COUNTIFS(Orders!$Z:$Z, $A9, Orders!$M:$M, "Return Received") -> 8 | AA9: =W9-Y9-Z9-V9 -> 0 | AB9: {=SUM(COUNTIFS(Orders!$Z:$Z, $A9, Orders!$M:$M, {"Returned","Returned to Shipper"}))} -> 0 | AC9: =COUNTIFS(Orders!$Z:$Z, $A9, Orders!$I:$I, "", Orders!$M:$M, "<>Cancelled") -> 0 | AD9: =SUMIFS(Orders!$U:$U, Orders!$Z:$Z, $A9, Orders!$M:$M, "Delivered") -> 80441 | AE9: =C9-AD9 -> 0 | AF9: =IFERROR(__xludf.DUMMYFUNCTION("IFERROR(TEXTJOIN("", "", TRUE, FILTER(Orders!$B$2:$B$2517, (TEXT(Orders!$D$2:$D$2517,""d-mmm"")=TEXT($A9,""d-mmm"")) * (ABS(Orders!$H$2:$H$2517 - Orders!$U$2:$U$2517) >= 1) * (Orders!$M$2:$M$2517=""Delivered""))), ""All Balanced"")"),"All Balanced") -> All Balanced | AG9: =IFERROR(__xludf.DUMMYFUNCTION("IFERROR(TEXTJOIN("", "", TRUE, FILTER(Orders!$I$2:$I$3000, (Orders!$M$2:$M$3000=""Delivered"") * (Orders!$N$2:$N$3000<>""Paid"") * (Orders!$Z$2:$Z$3000=$A9))), """")"),"") | AH9: =COUNTIFS(Orders!$M:$M, "Delivered", Orders!$N:$N, "<>Paid", Orders!$Z:$Z, $A9) -> 0
A10: 45997 | B10: =C10/Y10 -> 3091.05 | C10: =SUMIFS(Orders!$H:$H, Orders!$Z:$Z, $A10, Orders!$M:$M, "Delivered") -> 61821 | D10: =SUMIFS(Orders!$Q:$Q, Orders!$Z:$Z, $A10, Orders!$M:$M, "Delivered") -> 21310 | E10: =D10/C10 -> 0.34470487 | F10: =C10-(C10*4/100) -> 59348.16 | G10: =C10-F10 -> 2472.84 | H10: =C10-D10 -> 40511 | I10: =IFERROR(J10/C10, 0)*100 -> 43.842513 | J10: 27103.88 | L10: =(200*W10)+C10*4% -> 8472.84 | M10: =SUMIFS(Orders!$W:$W, Orders!$Z:$Z, $A10) -> 9083.4 | N10: =H10-J10-K10-M10 -> 4323.72 | O10: =Y10/W10*100 -> 66.666667 | P10: 4.1925512 | Q10: =J10/S10 -> 797.17294 | R10: =J10/W10 -> 903.46267 | S10: =COUNTIFS(Orders!$Z:$Z, $A10) -> 34 | T10: =COUNTIFS(Orders!$Z:$Z, $A10, Orders!$M:$M, "Cancelled") -> 4 | U10: =T10/S10 -> 0.11764706 | V10: =COUNTIFS(Orders!$Z:$Z, $A10, Orders!$M:$M, "pending") -> 0 | W10: =S10-T10 -> 30 | X10: =W10/S10 -> 0.88235294 | Y10: =COUNTIFS(Orders!$Z:$Z, $A10, Orders!$M:$M, "Delivered") -> 20 | Z10: =COUNTIFS(Orders!$Z:$Z, $A10, Orders!$M:$M, "Return Received") -> 10 | AA10: =W10-Y10-Z10-V10 -> 0 | AB10: {=SUM(COUNTIFS(Orders!$Z:$Z, $A10, Orders!$M:$M, {"Returned","Returned to Shipper"}))} -> 0 | AC10: =COUNTIFS(Orders!$Z:$Z, $A10, Orders!$I:$I, "", Orders!$M:$M, "<>Cancelled") -> 0 | AD10: =SUMIFS(Orders!$U:$U, Orders!$Z:$Z, $A10, Orders!$M:$M, "Delivered") -> 61821 | AE10: =C10-AD10 -> 0 | AF10: =IFERROR(__xludf.DUMMYFUNCTION("IFERROR(TEXTJOIN("", "", TRUE, FILTER(Orders!$B$2:$B$2517, (TEXT(Orders!$D$2:$D$2517,""d-mmm"")=TEXT($A10,""d-mmm"")) * (ABS(Orders!$H$2:$H$2517 - Orders!$U$2:$U$2517) >= 1) * (Orders!$M$2:$M$2517=""Delivered""))), ""All Balanced"")"),"All Balanced") -> All Balanced | AG10: =IFERROR(__xludf.DUMMYFUNCTION("IFERROR(TEXTJOIN("", "", TRUE, FILTER(Orders!$I$2:$I$3000, (Orders!$M$2:$M$3000=""Delivered"") * (Orders!$N$2:$N$3000<>""Paid"") * (Orders!$Z$2:$Z$3000=$A10))), """")"),"") | AH10: =COUNTIFS(Orders!$M:$M, "Delivered", Orders!$N:$N, "<>Paid", Orders!$Z:$Z, $A10) -> 0
A11: 45998 | B11: =C11/Y11 -> 2998.75 | C11: =SUMIFS(Orders!$H:$H, Orders!$Z:$Z, $A11, Orders!$M:$M, "Delivered") -> 83965 | D11: =SUMIFS(Orders!$Q:$Q, Orders!$Z:$Z, $A11, Orders!$M:$M, "Delivered") -> 28110 | E11: =D11/C11 -> 0.33478235 | F11: =C11-(C11*4/100) -> 80606.4 | G11: =C11-F11 -> 3358.6 | H11: =C11-D11 -> 55855 | I11: =IFERROR(J11/C11, 0)*100 -> 32.984815 | J11: 27695.7 | L11: =(200*W11)+C11*4% -> 10558.6 | M11: =SUMIFS(Orders!$W:$W, Orders!$Z:$Z, $A11) -> 11519.56 | N11: =H11-J11-K11-M11 -> 16639.74 | O11: =Y11/W11*100 -> 77.777778 | P11: 5.0577669 | Q11: =J11/S11 -> 659.42143 | R11: =J11/W11 -> 769.325 | S11: =COUNTIFS(Orders!$Z:$Z, $A11) -> 42 | T11: =COUNTIFS(Orders!$Z:$Z, $A11, Orders!$M:$M, "Cancelled") -> 6 | U11: =T11/S11 -> 0.14285714 | V11: =COUNTIFS(Orders!$Z:$Z, $A11, Orders!$M:$M, "pending") -> 0 | W11: =S11-T11 -> 36 | X11: =W11/S11 -> 0.85714286 | Y11: =COUNTIFS(Orders!$Z:$Z, $A11, Orders!$M:$M, "Delivered") -> 28 | Z11: =COUNTIFS(Orders!$Z:$Z, $A11, Orders!$M:$M, "Return Received") -> 8 | AA11: =W11-Y11-Z11-V11 -> 0 | AB11: {=SUM(COUNTIFS(Orders!$Z:$Z, $A11, Orders!$M:$M, {"Returned","Returned to Shipper"}))} -> 0 | AC11: =COUNTIFS(Orders!$Z:$Z, $A11, Orders!$I:$I, "", Orders!$M:$M, "<>Cancelled") -> 0 | AD11: =SUMIFS(Orders!$U:$U, Orders!$Z:$Z, $A11, Orders!$M:$M, "Delivered") -> 83965 | AE11: =C11-AD11 -> 0 | AF11: =IFERROR(__xludf.DUMMYFUNCTION("IFERROR(TEXTJOIN("", "", TRUE, FILTER(Orders!$B$2:$B$2517, (TEXT(Orders!$D$2:$D$2517,""d-mmm"")=TEXT($A11,""d-mmm"")) * (ABS(Orders!$H$2:$H$2517 - Orders!$U$2:$U$2517) >= 1) * (Orders!$M$2:$M$2517=""Delivered""))), ""All Balanced"")"),"All Balanced") -> All Balanced | AG11: =IFERROR(__xludf.DUMMYFUNCTION("IFERROR(TEXTJOIN("", "", TRUE, FILTER(Orders!$I$2:$I$3000, (Orders!$M$2:$M$3000=""Delivered"") * (Orders!$N$2:$N$3000<>""Paid"") * (Orders!$Z$2:$Z$3000=$A11))), """")"),"") | AH11: =COUNTIFS(Orders!$M:$M, "Delivered", Orders!$N:$N, "<>Paid", Orders!$Z:$Z, $A11) -> 0
A12: 45999 | B12: =C12/Y12 -> 3008.9 | C12: =SUMIFS(Orders!$H:$H, Orders!$Z:$Z, $A12, Orders!$M:$M, "Delivered") -> 87258.1 | D12: =SUMIFS(Orders!$Q:$Q, Orders!$Z:$Z, $A12, Orders!$M:$M, "Delivered") -> 32245 | E12: =D12/C12 -> 0.36953589 | F12: =C12-(C12*4/100) -> 83767.776 | G12: =C12-F12 -> 3490.324 | H12: =C12-D12 -> 55013.1 | I12: =IFERROR(J12/C12, 0)*100 -> 34.53441 | J12: 30134.07 | L12: =(200*W12)+C12*4% -> 11490.324 | M12: =SUMIFS(Orders!$W:$W, Orders!$Z:$Z, $A12) -> 11715.48 | N12: =H12-J12-K12-M12 -> 13163.55 | O12: =Y12/W12*100 -> 72.5 | P12: 5.4914452 | Q12: =J12/S12 -> 684.86523 | R12: =J12/W12 -> 753.35175 | S12: =COUNTIFS(Orders!$Z:$Z, $A12) -> 44 | T12: =COUNTIFS(Orders!$Z:$Z, $A12, Orders!$M:$M, "Cancelled") -> 4 | U12: =T12/S12 -> 0.090909091 | V12: =COUNTIFS(Orders!$Z:$Z, $A12, Orders!$M:$M, "pending") -> 0 | W12: =S12-T12 -> 40 | X12: =W12/S12 -> 0.90909091 | Y12: =COUNTIFS(Orders!$Z:$Z, $A12, Orders!$M:$M, "Delivered") -> 29 | Z12: =COUNTIFS(Orders!$Z:$Z, $A12, Orders!$M:$M, "Return Received") -> 11 | AA12: =W12-Y12-Z12-V12 -> 0 | AB12: {=SUM(COUNTIFS(Orders!$Z:$Z, $A12, Orders!$M:$M, {"Returned","Returned to Shipper"}))} -> 0 | AC12: =COUNTIFS(Orders!$Z:$Z, $A12, Orders!$I:$I, "", Orders!$M:$M, "<>Cancelled") -> 0 | AD12: =SUMIFS(Orders!$U:$U, Orders!$Z:$Z, $A12, Orders!$M:$M, "Delivered") -> 87258.1 | AE12: =C12-AD12 -> 0 | AF12: =IFERROR(__xludf.DUMMYFUNCTION("IFERROR(TEXTJOIN("", "", TRUE, FILTER(Orders!$B$2:$B$2517, (TEXT(Orders!$D$2:$D$2517,""d-mmm"")=TEXT($A12,""d-mmm"")) * (ABS(Orders!$H$2:$H$2517 - Orders!$U$2:$U$2517) >= 1) * (Orders!$M$2:$M$2517=""Delivered""))), ""All Balanced"")"),"All Balanced") -> All Balanced | AG12: =IFERROR(__xludf.DUMMYFUNCTION("IFERROR(TEXTJOIN("", "", TRUE, FILTER(Orders!$I$2:$I$3000, (Orders!$M$2:$M$3000=""Delivered"") * (Orders!$N$2:$N$3000<>""Paid"") * (Orders!$Z$2:$Z$3000=$A12))), """")"),"") | AH12: =COUNTIFS(Orders!$M:$M, "Delivered", Orders!$N:$N, "<>Paid", Orders!$Z:$Z, $A12) -> 0
A13: 46000 | B13: =C13/Y13 -> 2971.0556 | C13: =SUMIFS(Orders!$H:$H, Orders!$Z:$Z, $A13, Orders!$M:$M, "Delivered") -> 53479 | D13: =SUMIFS(Orders!$Q:$Q, Orders!$Z:$Z, $A13, Orders!$M:$M, "Delivered") -> 18605 | E13: =D13/C13 -> 0.34789357 | F13: =C13-(C13*4/100) -> 51339.84 | G13: =C13-F13 -> 2139.16 | H13: =C13-D13 -> 34874 | I13: =IFERROR(J13/C13, 0)*100 -> 50.432675 | J13: 26970.89 | L13: =(200*W13)+C13*4% -> 6539.16 | M13: =SUMIFS(Orders!$W:$W, Orders!$Z:$Z, $A13) -> 6871 | N13: =H13-J13-K13-M13 -> 1032.11 | O13: =Y13/W13*100 -> 81.818182 | P13: 2.670216 | Q13: =J13/S13 -> 1078.8356 | R13: =J13/W13 -> 1225.9495 | S13: =COUNTIFS(Orders!$Z:$Z, $A13) -> 25 | T13: =COUNTIFS(Orders!$Z:$Z, $A13, Orders!$M:$M, "Cancelled") -> 3 | U13: =T13/S13 -> 0.12 | V13: =COUNTIFS(Orders!$Z:$Z, $A13, Orders!$M:$M, "pending") -> 0 | W13: =S13-T13 -> 22 | X13: =W13/S13 -> 0.88 | Y13: =COUNTIFS(Orders!$Z:$Z, $A13, Orders!$M:$M, "Delivered") -> 18 | Z13: =COUNTIFS(Orders!$Z:$Z, $A13, Orders!$M:$M, "Return Received") -> 4 | AA13: =W13-Y13-Z13-V13 -> 0 | AB13: {=SUM(COUNTIFS(Orders!$Z:$Z, $A13, Orders!$M:$M, {"Returned","Returned to Shipper"}))} -> 0 | AC13: =COUNTIFS(Orders!$Z:$Z, $A13, Orders!$I:$I, "", Orders!$M:$M, "<>Cancelled") -> 0 | AD13: =SUMIFS(Orders!$U:$U, Orders!$Z:$Z, $A13, Orders!$M:$M, "Delivered") -> 53479 | AE13: =C13-AD13 -> 0 | AF13: =IFERROR(__xludf.DUMMYFUNCTION("IFERROR(TEXTJOIN("", "", TRUE, FILTER(Orders!$B$2:$B$2517, (TEXT(Orders!$D$2:$D$2517,""d-mmm"")=TEXT($A13,""d-mmm"")) * (ABS(Orders!$H$2:$H$2517 - Orders!$U$2:$U$2517) >= 1) * (Orders!$M$2:$M$2517=""Delivered""))), ""All Balanced"")"),"All Balanced") -> All Balanced | AG13: =IFERROR(__xludf.DUMMYFUNCTION("IFERROR(TEXTJOIN("", "", TRUE, FILTER(Orders!$I$2:$I$3000, (Orders!$M$2:$M$3000=""Delivered"") * (Orders!$N$2:$N$3000<>""Paid"") * (Orders!$Z$2:$Z$3000=$A13))), """")"),"") | AH13: =COUNTIFS(Orders!$M:$M, "Delivered", Orders!$N:$N, "<>Paid", Orders!$Z:$Z, $A13) -> 0
A14: 46001 | B14: =C14/Y14 -> 2917.0667 | C14: =SUMIFS(Orders!$H:$H, Orders!$Z:$Z, $A14, Orders!$M:$M, "Delivered") -> 87512 | D14: =SUMIFS(Orders!$Q:$Q, Orders!$Z:$Z, $A14, Orders!$M:$M, "Delivered") -> 32055 | E14: =D14/C14 -> 0.36629262 | F14: =C14-(C14*4/100) -> 84011.52 | G14: =C14-F14 -> 3500.48 | H14: =C14-D14 -> 55457 | I14: =IFERROR(J14/C14, 0)*100 -> 33.341439 | J14: 29177.76 | L14: =(200*W14)+C14*4% -> 12300.48 | M14: =SUMIFS(Orders!$W:$W, Orders!$Z:$Z, $A14) -> 13145 | N14: =H14-J14-K14-M14 -> 13134.24 | O14: =Y14/W14*100 -> 68.181818 | P14: 6.11248 | Q14: =J14/S14 -> 561.11077 | R14: =J14/W14 -> 663.13091 | S14: =COUNTIFS(Orders!$Z:$Z, $A14) -> 52 | T14: =COUNTIFS(Orders!$Z:$Z, $A14, Orders!$M:$M, "Cancelled") -> 8 | U14: =T14/S14 -> 0.15384615 | V14: =COUNTIFS(Orders!$Z:$Z, $A14, Orders!$M:$M, "pending") -> 0 | W14: =S14-T14 -> 44 | X14: =W14/S14 -> 0.84615385 | Y14: =COUNTIFS(Orders!$Z:$Z, $A14, Orders!$M:$M, "Delivered") -> 30 | Z14: =COUNTIFS(Orders!$Z:$Z, $A14, Orders!$M:$M, "Return Received") -> 14 | AA14: =W14-Y14-Z14-V14 -> 0 | AB14: {=SUM(COUNTIFS(Orders!$Z:$Z, $A14, Orders!$M:$M, {"Returned","Returned to Shipper"}))} -> 0 | AC14: =COUNTIFS(Orders!$Z:$Z, $A14, Orders!$I:$I, "", Orders!$M:$M, "<>Cancelled") -> 0 | AD14: =SUMIFS(Orders!$U:$U, Orders!$Z:$Z, $A14, Orders!$M:$M, "Delivered") -> 87512 | AE14: =C14-AD14 -> 0 | AF14: =IFERROR(__xludf.DUMMYFUNCTION("IFERROR(TEXTJOIN("", "", TRUE, FILTER(Orders!$B$2:$B$2517, (TEXT(Orders!$D$2:$D$2517,""d-mmm"")=TEXT($A14,""d-mmm"")) * (ABS(Orders!$H$2:$H$2517 - Orders!$U$2:$U$2517) >= 1) * (Orders!$M$2:$M$2517=""Delivered""))), ""All Balanced"")"),"All Balanced") -> All Balanced | AG14: =IFERROR(__xludf.DUMMYFUNCTION("IFERROR(TEXTJOIN("", "", TRUE, FILTER(Orders!$I$2:$I$3000, (Orders!$M$2:$M$3000=""Delivered"") * (Orders!$N$2:$N$3000<>""Paid"") * (Orders!$Z$2:$Z$3000=$A14))), """")"),"") | AH14: =COUNTIFS(Orders!$M:$M, "Delivered", Orders!$N:$N, "<>Paid", Orders!$Z:$Z, $A14) -> 0
A15: 46002 | B15: =C15/Y15 -> 3448.9583 | C15: =SUMIFS(Orders!$H:$H, Orders!$Z:$Z, $A15, Orders!$M:$M, "Delivered") -> 82775 | D15: =SUMIFS(Orders!$Q:$Q, Orders!$Z:$Z, $A15, Orders!$M:$M, "Delivered") -> 31615 | E15: =D15/C15 -> 0.38193899 | F15: =C15-(C15*4/100) -> 79464 | G15: =C15-F15 -> 3311 | H15: =C15-D15 -> 51160 | I15: =IFERROR(J15/C15, 0)*100 -> 32.705056 | J15: 27071.61 | L15: =(200*W15)+C15*4% -> 10711 | M15: =SUMIFS(Orders!$W:$W, Orders!$Z:$Z, $A15) -> 10944.16 | N15: =H15-J15-K15-M15 -> 13144.23 | O15: =Y15/W15*100 -> 64.864865 | P15: 5.6255955 | Q15: =J15/S15 -> 676.79025 | R15: =J15/W15 -> 731.66514 | S15: =COUNTIFS(Orders!$Z:$Z, $A15) -> 40 | T15: =COUNTIFS(Orders!$Z:$Z, $A15, Orders!$M:$M, "Cancelled") -> 3 | U15: =T15/S15 -> 0.075 | V15: =COUNTIFS(Orders!$Z:$Z, $A15, Orders!$M:$M, "pending") -> 0 | W15: =S15-T15 -> 37 | X15: =W15/S15 -> 0.925 | Y15: =COUNTIFS(Orders!$Z:$Z, $A15, Orders!$M:$M, "Delivered") -> 24 | Z15: =COUNTIFS(Orders!$Z:$Z, $A15, Orders!$M:$M, "Return Received") -> 13 | AA15: =W15-Y15-Z15-V15 -> 0 | AB15: {=SUM(COUNTIFS(Orders!$Z:$Z, $A15, Orders!$M:$M, {"Returned","Returned to Shipper"}))} -> 0 | AC15: =COUNTIFS(Orders!$Z:$Z, $A15, Orders!$I:$I, "", Orders!$M:$M, "<>Cancelled") -> 0 | AD15: =SUMIFS(Orders!$U:$U, Orders!$Z:$Z, $A15, Orders!$M:$M, "Delivered") -> 82775 | AE15: =C15-AD15 -> 0 | AF15: =IFERROR(__xludf.DUMMYFUNCTION("IFERROR(TEXTJOIN("", "", TRUE, FILTER(Orders!$B$2:$B$2517, (TEXT(Orders!$D$2:$D$2517,""d-mmm"")=TEXT($A15,""d-mmm"")) * (ABS(Orders!$H$2:$H$2517 - Orders!$U$2:$U$2517) >= 1) * (Orders!$M$2:$M$2517=""Delivered""))), ""All Balanced"")"),"All Balanced") -> All Balanced | AG15: =IFERROR(__xludf.DUMMYFUNCTION("IFERROR(TEXTJOIN("", "", TRUE, FILTER(Orders!$I$2:$I$3000, (Orders!$M$2:$M$3000=""Delivered"") * (Orders!$N$2:$N$3000<>""Paid"") * (Orders!$Z$2:$Z$3000=$A15))), """")"),"") | AH15: =COUNTIFS(Orders!$M:$M, "Delivered", Orders!$N:$N, "<>Paid", Orders!$Z:$Z, $A15) -> 0
A16: 46003 | B16: =C16/Y16 -> 3021.2581 | C16: =SUMIFS(Orders!$H:$H, Orders!$Z:$Z, $A16, Orders!$M:$M, "Delivered") -> 93659 | D16: =SUMIFS(Orders!$Q:$Q, Orders!$Z:$Z, $A16, Orders!$M:$M, "Delivered") -> 32815 | E16: =D16/C16 -> 0.35036676 | F16: =C16-(C16*4/100) -> 89912.64 | G16: =C16-F16 -> 3746.36 | H16: =C16-D16 -> 60844 | I16: =IFERROR(J16/C16, 0)*100 -> 29.619994 | J16: 27741.79 | L16: =(200*W16)+C16*4% -> 12346.36 | M16: =SUMIFS(Orders!$W:$W, Orders!$Z:$Z, $A16) -> 12480.2 | N16: =H16-J16-K16-M16 -> 20622.01 | O16: =Y16/W16*100 -> 72.093023 | P16: 5.8835891 | Q16: =J16/S16 -> 554.8358 | R16: =J16/W16 -> 645.15791 | S16: =COUNTIFS(Orders!$Z:$Z, $A16) -> 50 | T16: =COUNTIFS(Orders!$Z:$Z, $A16, Orders!$M:$M, "Cancelled") -> 7 | U16: =T16/S16 -> 0.14 | V16: =COUNTIFS(Orders!$Z:$Z, $A16, Orders!$M:$M, "pending") -> 0 | W16: =S16-T16 -> 43 | X16: =W16/S16 -> 0.86 | Y16: =COUNTIFS(Orders!$Z:$Z, $A16, Orders!$M:$M, "Delivered") -> 31 | Z16: =COUNTIFS(Orders!$Z:$Z, $A16, Orders!$M:$M, "Return Received") -> 12 | AA16: =W16-Y16-Z16-V16 -> 0 | AB16: {=SUM(COUNTIFS(Orders!$Z:$Z, $A16, Orders!$M:$M, {"Returned","Returned to Shipper"}))} -> 0 | AC16: =COUNTIFS(Orders!$Z:$Z, $A16, Orders!$I:$I, "", Orders!$M:$M, "<>Cancelled") -> 0 | AD16: =SUMIFS(Orders!$U:$U, Orders!$Z:$Z, $A16, Orders!$M:$M, "Delivered") -> 93659 | AE16: =C16-AD16 -> 0 | AF16: =IFERROR(__xludf.DUMMYFUNCTION("IFERROR(TEXTJOIN("", "", TRUE, FILTER(Orders!$B$2:$B$2517, (TEXT(Orders!$D$2:$D$2517,""d-mmm"")=TEXT($A16,""d-mmm"")) * (ABS(Orders!$H$2:$H$2517 - Orders!$U$2:$U$2517) >= 1) * (Orders!$M$2:$M$2517=""Delivered""))), ""All Balanced"")"),"All Balanced") -> All Balanced | AG16: =IFERROR(__xludf.DUMMYFUNCTION("IFERROR(TEXTJOIN("", "", TRUE, FILTER(Orders!$I$2:$I$3000, (Orders!$M$2:$M$3000=""Delivered"") * (Orders!$N$2:$N$3000<>""Paid"") * (Orders!$Z$2:$Z$3000=$A16))), """")"),"") | AH16: =COUNTIFS(Orders!$M:$M, "Delivered", Orders!$N:$N, "<>Paid", Orders!$Z:$Z, $A16) -> 0
A17: 46004 | B17: =C17/Y17 -> 2908.76 | C17: =SUMIFS(Orders!$H:$H, Orders!$Z:$Z, $A17, Orders!$M:$M, "Delivered") -> 72719 | D17: =SUMIFS(Orders!$Q:$Q, Orders!$Z:$Z, $A17, Orders!$M:$M, "Delivered") -> 24860 | E17: =D17/C17 -> 0.34186389 | F17: =C17-(C17*4/100) -> 69810.24 | G17: =C17-F17 -> 2908.76 | H17: =C17-D17 -> 47859 | I17: =IFERROR(J17/C17, 0)*100 -> 39.272652 | J17: 28558.68 | L17: =(200*W17)+C17*4% -> 10708.76 | M17: =SUMIFS(Orders!$W:$W, Orders!$Z:$Z, $A17) -> 10993.4 | N17: =H17-J17-K17-M17 -> 8306.92 | O17: =Y17/W17*100 -> 64.102564 | P17: 5.2264348 | Q17: =J17/S17 -> 607.63149 | R17: =J17/W17 -> 732.27385 | S17: =COUNTIFS(Orders!$Z:$Z, $A17) -> 47 | T17: =COUNTIFS(Orders!$Z:$Z, $A17, Orders!$M:$M, "Cancelled") -> 8 | U17: =T17/S17 -> 0.17021277 | V17: =COUNTIFS(Orders!$Z:$Z, $A17, Orders!$M:$M, "pending") -> 0 | W17: =S17-T17 -> 39 | X17: =W17/S17 -> 0.82978723 | Y17: =COUNTIFS(Orders!$Z:$Z, $A17, Orders!$M:$M, "Delivered") -> 25 | Z17: =COUNTIFS(Orders!$Z:$Z, $A17, Orders!$M:$M, "Return Received") -> 14 | AA17: =W17-Y17-Z17-V17 -> 0 | AB17: {=SUM(COUNTIFS(Orders!$Z:$Z, $A17, Orders!$M:$M, {"Returned","Returned to Shipper"}))} -> 0 | AC17: =COUNTIFS(Orders!$Z:$Z, $A17, Orders!$I:$I, "", Orders!$M:$M, "<>Cancelled") -> 0 | AD17: =SUMIFS(Orders!$U:$U, Orders!$Z:$Z, $A17, Orders!$M:$M, "Delivered") -> 72719 | AE17: =C17-AD17 -> 0 | AF17: =IFERROR(__xludf.DUMMYFUNCTION("IFERROR(TEXTJOIN("", "", TRUE, FILTER(Orders!$B$2:$B$2517, (TEXT(Orders!$D$2:$D$2517,""d-mmm"")=TEXT($A17,""d-mmm"")) * (ABS(Orders!$H$2:$H$2517 - Orders!$U$2:$U$2517) >= 1) * (Orders!$M$2:$M$2517=""Delivered""))), ""All Balanced"")"),"All Balanced") -> All Balanced | AG17: =IFERROR(__xludf.DUMMYFUNCTION("IFERROR(TEXTJOIN("", "", TRUE, FILTER(Orders!$I$2:$I$3000, (Orders!$M$2:$M$3000=""Delivered"") * (Orders!$N$2:$N$3000<>""Paid"") * (Orders!$Z$2:$Z$3000=$A17))), """")"),"") | AH17: =COUNTIFS(Orders!$M:$M, "Delivered", Orders!$N:$N, "<>Paid", Orders!$Z:$Z, $A17) -> 0
